Workbook

Sheet BASE
A1: Proyecto | B1: Líder | C1: Empleados | D1: Rol | E1: Actividades | F1: Horas | G1: Costo Hora | H1: Fecha Inicio | I1: Fecha Fin
A2: 1 | B2: Carlos Ruiz | C2: Ana, Pedro | D2: Diseñadora, Tester | E2: Diseño UI, Pruebas | F2: 80,100 | G2: 30.000,25.000 | H2: 2025-02-01 | I2: 2025-05-01
A3: 2 | B3: Marta Díaz | C3: Luis | D3: Analista | E3: Levantamiento | F3: 120 | G3: 28.000 | H3: 2025-03-01 | I3: 2025-06-01
A4: 3 | B4: Carlos Quintero | C4: Daniel Torres, Andrés Zea, Marta García | D4: Scrum Master, QA, Analista | E4: Deploy, Mantenimiento | F4: 143,199 | G4: 43419,42705,50831 | H4: 2025-01-09 | I4: 2025-03-15
A5: 4 | B5: Andrés García | C5: Valentina García | D5: Tester | E5: Documentación, Levantamiento | F5: 167,127 | G5: 24850 | H5: 2025-03-26 | I5: 2025-06-12
A6: 5 | B6: Luis Quintero | C6: Daniel Ruiz | D6: Diseñadora | E6: Deploy, Mantenimiento | F6: 195,82 | G6: 20813 | H6: 2025-02-19 | I6: 2025-05-30
A7: 6 | B7: Andrés Torres | C7: Marta Torres | D7: QA | E7: Desarrollo Backend, Desarrollo Frontend | F7: 193,40 | G7: 53881 | H7: 2025-03-08 | I7: 2025-06-02
A8: 7 | B8: Valentina Zea | C8: Julián Quintero | D8: Analista | E8: Desarrollo Backend, Desarrollo Frontend | F8: 46,106 | G8: 52727 | H8: 2025-02-23 | I8: 2025-06-19
A9: 8 | B9: Ana Zea | C9: Pedro Ruiz, Andrés Ramírez | D9: Tester, Product Owner | E9: Planeación Sprint | F9: 61 | G9: 34221,40798 | H9: 2025-03-18 | I9: 2025-06-16
A10: 9 | B10: Sofía López | C10: Andrés Zea, Daniel Ruiz, Andrés Gómez | D10: Desarrollador, Diseñadora, Analista | E10: Desarrollo Backend, Desarrollo Frontend | F10: 43,175 | G10: 37237,56301,27565 | H10: 2025-03-19 | I10: 2025-05-01
A11: 10 | B11: Andrés Díaz | C11: Valentina Quintero, Camila López, Sofía Torres | D11: Diseñadora, Tester, Scrum Master | E11: Deploy, Mantenimiento | F11: 72,47 | G11: 24690,35179,41511 | H11: 2025-01-22 | I11: 2025-02-24
A12: 11 | B12: Andrés Quintero | C12: Luis Ramírez, Camila Díaz | D12: Analista, Analista | E12: Planeación Sprint | F12: 99 | G12: 23646,35897 | H12: 2025-02-15 | I12: 2025-06-15
A13: 12 | B13: Ana Quintero | C13: Marta Ruiz | D13: Desarrollador | E13: Planeación Sprint | F13: 50 | G13: 37463 | H13: 2025-01-16 | I13: 2025-05-19
... A501: 500 | B501: Carlos Gómez | C501: Carlos Quintero, Sofía Quintero, Daniel Ramírez | D501: Scrum Master, QA, Diseñadora | E501: Revisión Código, Ajustes finales | F501: 80,174 | G501: 31519,32282,41703 | H501: 2025-01-12 | I501: 2025-02-18

Sheet 0FN
A1: Proyecto | B1: Líder | C1: Empleados | D1: Empleado2 | E1: Empleada3 | F1: Rol | G1: Rol2 | H1: Rol3 | I1: Actividades | K1: Horas | L1: Costo hora | N1: Fecha Inicio | O1: Fecha Fin
A2: 1 | B2: Carlos Ruiz | C2: Ana | D2: Pedro | F2: Diseñadora | G2: Tester | I2: Diseño UI | J2: Pruebas | K2: 80,100 | N2: 2025-02-01 | O2: 2025-05-01
A3: 2 | B3: Marta Díaz | C3: Luis | F3: Analista | I3: Levantamiento | K3: 120 | N3: 2025-03-01 | O3: 2025-06-01
A4: 3 | B4: Carlos Quintero | C4: Daniel Torres | D4: Andrés Zea | E4: Marta García | F4: Scrum Master | G4: QA | H4: Analista | I4: Deploy | J4: Mantenimiento | K4: 143,199 | N4: 2025-01-09 | O4: 2025-03-15
A5: 4 | B5: Andrés García | C5: Valentina García | F5: Tester | I5: Documentación | J5: Levantamiento | K5: 167,127 | N5: 2025-03-26 | O5: 2025-06-12
A6: 5 | B6: Luis Quintero | C6: Daniel Ruiz | F6: Diseñadora | I6: Deploy | J6: Mantenimiento | K6: 195,82 | N6: 2025-02-19 | O6: 2025-05-30
A7: 6 | B7: Andrés Torres | C7: Marta Torres | F7: QA | I7: Desarrollo Backend | J7: Desarrollo Frontend | K7: 193,40 | N7: 2025-03-08 | O7: 2025-06-02
A8: 7 | B8: Valentina Zea | C8: Julián Quintero | F8: Analista | I8: Desarrollo Backend | J8: Desarrollo Frontend | K8: 46,106 | N8: 2025-02-23 | O8: 2025-06-19
A9: 8 | B9: Ana Zea | C9: Pedro Ruiz | D9: Andrés Ramírez | F9: Tester | G9: Product Owner | I9: Planeación Sprint | K9: 61 | N9: 2025-03-18 | O9: 2025-06-16
A10: 9 | B10: Sofía López | C10: Andrés Zea | D10: Daniel Ruiz | E10: Andrés Gómez | F10: Desarrollador | G10: Diseñadora | H10: Analista | I10: Desarrollo Backend | J10: Desarrollo Frontend | K10: 43,175 | N10: 2025-03-19 | O10: 2025-05-01
A11: 10 | B11: Andrés Díaz | C11: Valentina Quintero | D11: Camila López | E11: Sofía Torres | F11: Diseñadora | G11: Tester | H11: Scrum Master | I11: Deploy | J11: Mantenimiento | K11: 72,47 | N11: 2025-01-22 | O11: 2025-02-24
A12: 11 | B12: Andrés Quintero | C12: Luis Ramírez | D12: Camila Díaz | F12: Analista | G12: Analista | I12: Planeación Sprint | K12: 99 | N12: 2025-02-15 | O12: 2025-06-15
A13: 12 | B13: Ana Quintero | C13: Marta Ruiz | F13: Desarrollador | I13: Planeación Sprint | K13: 50 | N13: 2025-01-16 | O13: 2025-05-19
A14: 13 | B14: Ana Torres | C14: Julián García | D14: Luis Torres | E14: Andrés Zea | F14: Product Owner | G14: Scrum Master | H14: Product Owner | I14: Desarrollo Backend | J14: Desarrollo Frontend | K14: 53,94 | N14: 2025-01-07 | O14: 2025-04-22
A15: 14 | B15: Luis Gómez | C15: Julián Martínez | D15: Luis García | E15: Ana López | F15: Diseñadora | G15: QA | H15: Product Owner | I15: Deploy | J15: Mantenimiento | K15: 109,180 | N15: 2025-02-04 | O15: 2025-07-01
A16: 15 | B16: Ana Torres | C16: Julián Torres | D16: Sofía Quintero | F16: Scrum Master | G16: Diseñadora | I16: Documentación | J16: Levantamiento | K16: 141,63 | N16: 2025-01-07 | O16: 2025-05-23
A17: 16 | B17: Pedro Ruiz | C17: Camila Ruiz | D17: Valentina García | E17: Ana Ruiz | F17: Diseñadora | G17: Scrum Master | H17: Diseñadora | I17: Deploy | J17: Mantenimiento | K17: 197,187 | N17: 2025-02-27 | O17: 2025-06-11
A18: 17 | B18: Marta Ruiz | C18: Luis Gómez | D18: Luis Zea | F18: Scrum Master | G18: Diseñadora | I18: Documentación | J18: Levantamiento | K18: 172,134 | N18: 2025-01-04 | O18: 2025-05-08
A19: 18 | B19: Julián Zea | C19: Julián Gómez | D19: Sofía Ramírez | E19: Andrés Díaz | F19: Tester | G19: Diseñadora | H19: Desarrollador | I19: Diseño UI | J19: Pruebas | K19: 152,197 | N19: 2025-01-07 | O19: 2025-02-16
A20: 19 | B20: Pedro Zea | C20: Valentina García | D20: Julián Ruiz | F20: Tester | G20: Diseñadora | I20: Revisión Código | J20: Ajustes finales | K20: 156,52 | N20: 2025-01-11 | O20: 2025-02-17
A21: 20 | B21: Sofía Martínez | C21: Camila García | D21: Andrés García | E21: Carlos López | F21: Diseñadora | G21: Product Owner | H21: Desarrollador | I21: Planeación Sprint | K21: 90 | N21: 2025-01-03 | O21: 2025-02-04
A22: 21 | B22: Carlos Gómez | C22: Luis Ramírez | F22: Tester | I22: Planeación Sprint | K22: 168 | N22: 2025-01-30 | O22: 2025-04-21
A23: 22 | B23: Carlos Quintero | C23: Luis Díaz | D23: Carlos Zea | F23: Scrum Master | G23: Product Owner | I23: Diseño UI | J23: Pruebas | K23: 198,99 | N23: 2025-03-19 | O23: 2025-05-10
A24: 23 | B24: Valentina Díaz | C24: Julián Quintero | D24: Sofía López | F24: Product Owner | G24: Product Owner | I24: Diseño UI | J24: Pruebas | K24: 56,187 | N24: 2025-03-21 | O24: 2025-04-20
A25: 24 | B25: Carlos Ruiz | C25: Valentina García | F25: Product Owner | I25: Diseño UI | J25: Pruebas | K25: 100,124 | N25: 2025-02-27 | O25: 2025-04-06
A26: 25 | B26: Valentina Quintero | C26: Marta Quintero | F26: Tester | I26: Revisión Código | J26: Ajustes finales | K26: 143,151 | N26: 2025-01-26 | O26: 2025-06-13
A27: 26 | B27: Luis Díaz | C27: Luis Gómez | D27: Sofía Martínez | E27: Andrés Martínez | F27: Desarrollador | G27: Tester | H27: QA | I27: Documentación | J27: Levantamiento | K27: 159,158 | N27: 2025-03-03 | O27: 2025-05-27
A28: 27 | B28: Daniel Díaz | C28: Marta García | D28: Ana Zea | F28: QA | G28: Diseñadora | I28: Revisión Código | J28: Ajustes finales | K28: 135,188 | N28: 2025-03-20 | O28: 2025-05-16
A29: 28 | B29: Carlos Ruiz | C29: Sofía García | D29: Pedro Ruiz | F29: QA | G29: Tester | I29: Deploy | J29: Mantenimiento | K29: 142,51 | N29: 2025-02-13 | O29: 2025-04-06
A30: 29 | B30: Daniel Gómez | C30: Luis Ruiz | D30: Julián Torres | F30: Diseñadora | G30: Scrum Master | I30: Revisión Código | J30: Ajustes finales | K30: 130,121 | N30: 2025-01-07 | O30: 2025-02-19
A31: 30 | B31: Ana Ramírez | C31: Ana Ramírez | F31: Product Owner | I31: Documentación | J31: Levantamiento | K31: 47,42 | N31: 2025-01-18 | O31: 2025-06-06
A32: 31 | B32: Andrés López | C32: Marta Torres | D32: Luis Martínez | E32: Luis Torres | F32: Analista | G32: Analista | H32: QA | I32: Deploy | J32: Mantenimiento | K32: 49,191 | N32: 2025-03-01 | O32: 2025-06-19
A33: 32 | B33: Luis Díaz | C33: Valentina Torres | D33: Ana Díaz | E33: Camila Martínez | F33: Tester | G33: Scrum Master | H33: Desarrollador | I33: Desarrollo Backend | J33: Desarrollo Frontend | K33: 137,49 | N33: 2025-02-20 | O33: 2025-06-12
A34: 33 | B34: Marta Ruiz | C34: Andrés Martínez | D34: Marta Ruiz | E34: Camila García | F34: Analista | G34: Analista | H34: Diseñadora | I34: Diseño UI | J34: Pruebas | K34: 78,149 | N34: 2025-01-12 | O34: 2025-02-21
A35: 34 | B35: Pedro Ruiz | C35: Luis Zea | F35: Scrum Master | I35: Deploy | J35: Mantenimiento | K35: 132,107 | N35: 2025-03-18 | O35: 2025-05-06
A36: 35 | B36: Daniel Martínez | C36: Carlos Quintero | D36: Marta Díaz | E36: Carlos García | F36: Diseñadora | G36: Scrum Master | H36: Analista | I36: Revisión Código | J36: Ajustes finales | K36: 60,142 | N36: 2025-03-07 | O36: 2025-04-28
A37: 36 | B37: Andrés Zea | C37: Camila Díaz | D37: Camila Díaz | E37: Luis Torres | F37: Product Owner | G37: Analista | H37: Scrum Master | I37: Diseño UI | J37: Pruebas | K37: 62,166 | N37: 2025-03-23 | O37: 2025-04-24
A38: 37 | B38: Camila Ruiz | C38: Sofía Quintero | F38: Scrum Master | I38: Revisión Código | J38: Ajustes finales | K38: 45,71 | N38: 2025-03-19 | O38: 2025-05-15
A39: 38 | B39: Ana López | C39: Sofía Martínez | D39: Sofía Quintero | E39: Luis Ruiz | F39: Desarrollador | G39: QA | H39: Tester | I39: Planeación Sprint | K39: 56 | N39: 2025-02-09 | O39: 2025-06-17
A40: 39 | B40: Julián Díaz | C40: Ana Ruiz | F40: Desarrollador | I40: Deploy | J40: Mantenimiento | K40: 68,176 | N40: 2025-03-20 | O40: 2025-07-27
...

Sheet CIUDADES
A1: id_ciudad (PK)(*) | B1: nombre_ciudad (*)
A2: 1 | B2: Bogotá
A3: 2 | B3: Medellín
A4: 3 | B4: Bucaramanga
A5: 4 | B5: Barranquilla
A6: 5 | B6: Cali

Sheet LIDER
A1: id_líder (PK)(*) | B1: tipo_doc_lider (*)(FK)1:1 | C1: num_doc_lider (*) | D1: nombre1_líder (*) | E1: nombre2_líder | F1: apellido1_líder (*) | G1: apellido2_líder | H1: direccion(*) | I1: correo(*) | J1: ciudad(*)FK (1:1) | K1: Telefono(*)
A2: 1 | B2: =TIPO_DOC!A2 -> 1 | C2: 123456789 | D2: Carlos | E2: mario | F2: Ruiz | H2: Calle 7 #4-16 | I2: =_xlfn.CONCAT(D2,"_",LEFT(F2,3),CHOOSE(RANDBETWEEN(1,2),"@gmail.com","@hotmail.com")) -> Carlos_Rui@hotmail.com | J2: {=CIUDADES!A2:A6} -> 1 | K2: 3216549874
A3: 2 | B3: =TIPO_DOC!A2 -> 1 | C3: 345678987654 | D3: Marta | F3: Díaz | G3: quintero | H3: Calle 27 # 11-35 | I3: =_xlfn.CONCAT(D3,"_",LEFT(F3,3),CHOOSE(RANDBETWEEN(1,2),"@gmail.com","@hotmail.com")) -> Marta_Día@hotmail.com | J3: 2 | K3: 6564825521
A4: 3 | B4: =TIPO_DOC!A2 -> 1 | C4: 523346754 | D4: Carlos | E4: andres | F4: Quintero | H4: Calle 66 # 5-43 | I4: =_xlfn.CONCAT(D4,"_",LEFT(F4,3),CHOOSE(RANDBETWEEN(1,2),"@gmail.com","@hotmail.com")) -> Carlos_Qui@hotmail.com | J4: 3 | K4: 6886516545
A5: 4 | B5: =TIPO_DOC!A2 -> 1 | C5: 65435643 | D5: Andrés | F5: García | G5: estrada | H5: Calle 29 # 9-26 | I5: =_xlfn.CONCAT(D5,"_",LEFT(F5,3),CHOOSE(RANDBETWEEN(1,2),"@gmail.com","@hotmail.com")) -> Andrés_Gar@gmail.com | J5: 4 | K5: 3354464215
A6: 5 | B6: =TIPO_DOC!A$2 -> 1 | C6: 234334534 | D6: Luis | E6: fernando | F6: Quintero | H6: Calle 95 # 7-15 | I6: =_xlfn.CONCAT(D6,"_",LEFT(F6,3),CHOOSE(RANDBETWEEN(1,2),"@gmail.com","@hotmail.com")) -> Luis_Qui@hotmail.com | J6: 5 | K6: 6651352115
A7: 6 | B7: =TIPO_DOC!A$2 -> 1 | C7: 45433434 | D7: Andrés | F7: Torres | G7: loaiza | H7: Calle 93 # 14-10 | I7: =_xlfn.CONCAT(D7,"_",LEFT(F7,3),CHOOSE(RANDBETWEEN(1,2),"@gmail.com","@hotmail.com")) -> Andrés_Tor@gmail.com | J7: {=CIUDADES!A2:A6} -> 1 | K7: 5212122222
A8: 7 | B8: =TIPO_DOC!A$2 -> 1 | C8: 23454345 | D8: Valentina | F8: Zea | G8: lora | H8: Calle 54 # 1-32 | I8: =_xlfn.CONCAT(D8,"_",LEFT(F8,3),CHOOSE(RANDBETWEEN(1,2),"@gmail.com","@hotmail.com")) -> Valentina_Zea@hotmail.com | J8: 2 | K8: 5425135155
A9: 8 | B9: =TIPO_DOC!A$2 -> 1 | C9: 2333434 | D9: Ana | E9: maria | F9: Zea | H9: Calle 15 # 11-17 | I9: =_xlfn.CONCAT(D9,"_",LEFT(F9,3),CHOOSE(RANDBETWEEN(1,2),"@gmail.com","@hotmail.com")) -> Ana_Zea@hotmail.com | J9: 3 | K9: 3536622222
A10: 9 | B10: =TIPO_DOC!A$2 -> 1 | C10: 2343434534 | D10: Sofía | E10: aria | F10: López | H10: Calle 89 # 14-20 | I10: =_xlfn.CONCAT(D10,"_",LEFT(F10,3),CHOOSE(RANDBETWEEN(1,2),"@gmail.com","@hotmail.com")) -> Sofía_Lóp@gmail.com | J10: 4 | K10: 2312626235
A11: 10 | B11: =TIPO_DOC!A$2 -> 1 | C11: 3434345 | D11: Andrés | F11: Díaz | G11: galarga | H11: Calle 90 # 19-20 | I11: =_xlfn.CONCAT(D11,"_",LEFT(F11,3),CHOOSE(RANDBETWEEN(1,2),"@gmail.com","@hotmail.com")) -> Andrés_Día@gmail.com | J11: 5 | K11: 6556565165
A12: 11 | B12: =TIPO_DOC!A$2 -> 1 | C12: 3453453 | D12: Andrés | F12: Quintero | H12: Calle 72 # 14-11 | I12: =_xlfn.CONCAT(D12,"_",LEFT(F12,3),CHOOSE(RANDBETWEEN(1,2),"@gmail.com","@hotmail.com")) -> Andrés_Qui@hotmail.com | J12: {=CIUDADES!A2:A6} -> 1 | K12: 12345434534
A13: 12 | B13: =TIPO_DOC!A$2 -> 1 | C13: 34544534 | D13: Ana | E13: maria | F13: Quintero | H13: Calle 18 # 1-33 | I13: =_xlfn.CONCAT(D13,"_",LEFT(F13,3),CHOOSE(RANDBETWEEN(1,2),"@gmail.com","@hotmail.com")) -> Ana_Qui@gmail.com | J13: 2 | K13: 1.1093439e+10
A14: 13 | B14: =TIPO_DOC!A$2 -> 1 | C14: 1.7365686e+08 | D14: Ana | E14: maria | F14: Torres | H14: Calle 47 # 11-9 | I14: =_xlfn.CONCAT(D14,"_",LEFT(F14,3),CHOOSE(RANDBETWEEN(1,2),"@gmail.com","@hotmail.com")) -> Ana_Tor@gmail.com | J14: 3 | K14: 1.2779493e+10
A15: 14 | B15: =TIPO_DOC!A$2 -> 1 | C15: 1.0848002e+08 | D15: Luis | F15: Gómez | G15: torres | H15: Calle 65 # 17-1 | I15: =_xlfn.CONCAT(D15,"_",LEFT(F15,3),CHOOSE(RANDBETWEEN(1,2),"@gmail.com","@hotmail.com")) -> Luis_Góm@hotmail.com | J15: 4 | K15: 1.4465548e+10
A16: 15 | B16: =TIPO_DOC!A$2 -> 1 | C16: 43303188 | D16: Pedro | E16: antonio | F16: Ruiz | H16: Calle 50 # 20-47 | I16: =_xlfn.CONCAT(D16,"_",LEFT(F16,3),CHOOSE(RANDBETWEEN(1,2),"@gmail.com","@hotmail.com")) -> Pedro_Rui@hotmail.com | J16: 5 | K16: 1.6151602e+10

Sheet PROYECTO
A1: id_proyecto (*) PK | B1: nombre_proyecto (*) | C1: decripcion_proyecto (*) | D1: lider_proyecto (*) (FK) N:1 | E1: fecha_inicio (*) | F1: fecha_fin (*)
A2: 1 | B2: Tester IA | C2: Sistema que pone a prueba modelos de inteligencia artificial mediante diferentes escenarios y casos de uso, evaluando su rendimiento, precisión y capacidad de respuesta ante distintos tipos de entradas. | D2: =LIDER!A2 -> 1 | E2: 46073 | F2: 46132
A3: 2 | B3: Evaluador de Intelecto | C3: Aplicación diseñada para medir habilidades cognitivas como razonamiento lógico, memoria y capacidad de análisis a través de pruebas estructuradas y resultados cuantificables. | D3: =LIDER!A3 -> 2 | E3: 46073 | F3: 46132
A4: 3 | B4: Generador de matriz | C4: Herramienta que crea matrices dinámicamente según parámetros definidos por el usuario (filas, columnas, valores), permitiendo realizar operaciones matemáticas o análisis estructural de datos. | D4: =LIDER!A4 -> 3 | E4: 46073 | F4: 46132
A5: 4 | B5: Calificador de materia | C5: Sistema que calcula la nota final de una asignatura a partir de diferentes porcentajes (tareas, exámenes, proyectos), generando resultados automáticos y reportes de desempeño. | D5: =LIDER!A5 -> 4 | E5: 46073 | F5: 46132
A6: 5 | B6: Promediador de nomina | C6: Aplicación que calcula promedios salariales considerando distintos factores como horas trabajadas, bonificaciones y descuentos, facilitando el análisis financiero y administrativo. | D6: =LIDER!A6 -> 5 | E6: 46073 | F6: 46132
A7: 6 | B7: Evaluador de calidad | C7: Sistema que analiza productos o procesos según criterios predefinidos, asignando puntajes o clasificaciones para determinar niveles de cumplimiento y estándares de calidad. | D7: =LIDER!A7 -> 6 | E7: 46073 | F7: 46132
A8: 7 | B8: Tester IA | C8: Sistema que pone a prueba modelos de inteligencia artificial mediante diferentes escenarios y casos de uso, evaluando su rendimiento, precisión y capacidad de respuesta ante distintos tipos de entradas. | D8: =LIDER!A8 -> 7 | E8: 46073 | F8: 46132
A9: 8 | B9: Evaluador de Intelecto | C9: Aplicación diseñada para medir habilidades cognitivas como razonamiento lógico, memoria y capacidad de análisis a través de pruebas estructuradas y resultados cuantificables. | D9: =LIDER!A9 -> 8 | E9: 46073 | F9: 46132
A10: 9 | B10: Generador de matriz | C10: Herramienta que crea matrices dinámicamente según parámetros definidos por el usuario (filas, columnas, valores), permitiendo realizar operaciones matemáticas o análisis estructural de datos. | D10: =LIDER!A10 -> 9 | E10: 46073 | F10: 46132
A11: 10 | B11: Calificador de materia | C11: Sistema que calcula la nota final de una asignatura a partir de diferentes porcentajes (tareas, exámenes, proyectos), generando resultados automáticos y reportes de desempeño. | D11: =LIDER!A11 -> 10 | E11: 46073 | F11: 46132

Sheet EMPLEADOS
A1: id_empleado(PK)(*) | B1: tipo_doc_empleado (*)1:1(FK) | C1: num_doc_empleado (*) | D1: nombre1_empleado (*) | E1: nombre2_empleado | F1: apellido1_empleado (*) | G1: apellido2_empleado | H1: Direccion (*) | I1: correo(*) | J1: ciudad(*)1:1(FK) | K1: Telefono(*) | U1: Rol | V1: Horas
A2: 1 | B2: =TIPO_DOC!A2 -> 1 | C2: 34354634212 | D2: Ana | F2: caballos | G2: gomez | H2: Cra 12 #9-21 | I2: =_xlfn.CONCAT(D2,"_",LEFT(F2,3),CHOOSE(RANDBETWEEN(1,2),"@gmail.com","@hotmail.com")) -> Ana_cab@gmail.com | J2: {=CIUDADES!A2:A6} -> 1 | K2: 46315252151 | U2: Diseñadora | V2: 80 | W2: 100
A3: 2 | B3: =TIPO_DOC!A2 -> 1 | C3: 1324543 | D3: Ana | E3: maria | F3: Díaz | H3: Calle 7 #4-16 | I3: =_xlfn.CONCAT(D3,"_",LEFT(F3,3),CHOOSE(RANDBETWEEN(1,2),"@gmail.com","@hotmail.com")) -> Ana_Día@gmail.com | J3: 2 | K3: 65465684685 | U3: Diseñadora | V3: 120
A4: 3 | B4: =TIPO_DOC!A2 -> 1 | C4: 43543442536 | D4: Ana | E4: mercedez | F4: García | H4: Calle 27 # 11-35 | I4: =_xlfn.CONCAT(D4,"_",LEFT(F4,3),CHOOSE(RANDBETWEEN(1,2),"@gmail.com","@hotmail.com")) -> Ana_Gar@gmail.com | J4: 3 | K4: 69856868 | U4: Diseñadora | V4: 143 | W4: 199
A5: 4 | B5: =TIPO_DOC!A2 -> 1 | C5: 43543435 | D5: Ana | F5: Gómez | G5: gomez | H5: Calle 66 # 5-43 | I5: =_xlfn.CONCAT(D5,"_",LEFT(F5,3),CHOOSE(RANDBETWEEN(1,2),"@gmail.com","@hotmail.com")) -> Ana_Góm@gmail.com | J5: 4 | K5: 685465468 | U5: Analista | V5: 167 | W5: 127
A6: 5 | B6: =TIPO_DOC!A2 -> 1 | C6: 235454536443 | D6: Ana | F6: López | G6: rammirez | H6: Calle 29 # 9-26 | I6: =_xlfn.CONCAT(D6,"_",LEFT(F6,3),CHOOSE(RANDBETWEEN(1,2),"@gmail.com","@hotmail.com")) -> Ana_Lóp@hotmail.com | J6: 5 | K6: 685465468 | U6: Scrum Master | V6: 195 | W6: 82
A7: 6 | B7: =TIPO_DOC!A2 -> 1 | C7: 436557 | D7: Ana | F7: Martínez | H7: Calle 95 # 7-15 | I7: =_xlfn.CONCAT(D7,"_",LEFT(F7,3),CHOOSE(RANDBETWEEN(1,2),"@gmail.com","@hotmail.com")) -> Ana_Mar@hotmail.com | J7: {=CIUDADES!A2:A6} -> 1 | K7: 685465468 | U7: Diseñadora | V7: 193 | W7: 40
A8: 7 | B8: =TIPO_DOC!A2 -> 1 | C8: 565567566543 | D8: Ana | F8: Quintero | G8: torres | H8: Calle 93 # 14-10 | I8: =_xlfn.CONCAT(D8,"_",LEFT(F8,3),CHOOSE(RANDBETWEEN(1,2),"@gmail.com","@hotmail.com")) -> Ana_Qui@hotmail.com | J8: 2 | K8: 685465468 | U8: Scrum Master | V8: 46 | W8: 106
A9: 8 | B9: =TIPO_DOC!A2 -> 1 | C9: 567435432 | D9: Ana | E9: sofia | F9: Ramírez | H9: Calle 54 # 1-32 | I9: =_xlfn.CONCAT(D9,"_",LEFT(F9,3),CHOOSE(RANDBETWEEN(1,2),"@gmail.com","@hotmail.com")) -> Ana_Ram@hotmail.com | J9: 3 | K9: 685465468 | U9: Desarrollador | V9: 61
A10: 9 | B10: =TIPO_DOC!A2 -> 1 | C10: 3455434 | D10: Ana | F10: Ruiz | G10: quintero | H10: Calle 15 # 11-17 | I10: =_xlfn.CONCAT(D10,"_",LEFT(F10,3),CHOOSE(RANDBETWEEN(1,2),"@gmail.com","@hotmail.com")) -> Ana_Rui@gmail.com | J10: 4 | K10: 685465468 | U10: QA | V10: 43 | W10: 175
A11: 10 | B11: =TIPO_DOC!A2 -> 1 | C11: 34554546356 | D11: Ana | E11: sofia | F11: Torres | H11: Calle 89 # 14-20 | I11: =_xlfn.CONCAT(D11,"_",LEFT(F11,3),CHOOSE(RANDBETWEEN(1,2),"@gmail.com","@hotmail.com")) -> Ana_Tor@hotmail.com | J11: 5 | K11: 685465468 | U11: Scrum Master | V11: 72 | W11: 47
A12: 11 | B12: =TIPO_DOC!A2 -> 1 | C12: 4565435653 | D12: Ana | F12: Zea | G12: estrada | H12: Calle 90 # 19-20 | I12: =_xlfn.CONCAT(D12,"_",LEFT(F12,3),CHOOSE(RANDBETWEEN(1,2),"@gmail.com","@hotmail.com")) -> Ana_Zea@gmail.com | J12: {=CIUDADES!A2:A6} -> 1 | K12: 685465468 | U12: Scrum Master | V12: 99
A13: 12 | B13: =TIPO_DOC!A2 -> 1 | C13: 678678868 | D13: Andrés | E13: antonio | F13: Díaz | H13: Calle 72 # 14-11 | I13: =_xlfn.CONCAT(D13,"_",LEFT(F13,3),CHOOSE(RANDBETWEEN(1,2),"@gmail.com","@hotmail.com")) -> Andrés_Día@gmail.com | J13: 2 | K13: 685465468 | U13: Desarrollador | V13: 50
A14: 13 | B14: =TIPO_DOC!A2 -> 1 | C14: 678768756 | D14: Andrés | E14: mario | F14: García | H14: Calle 18 # 1-33 | I14: =_xlfn.CONCAT(D14,"_",LEFT(F14,3),CHOOSE(RANDBETWEEN(1,2),"@gmail.com","@hotmail.com")) -> Andrés_Gar@hotmail.com | J14: 3 | K14: 685465468 | U14: Analista | V14: 53 | W14: 94
A15: 14 | B15: =TIPO_DOC!A2 -> 1 | C15: 6787567668 | D15: Andrés | F15: Gómez | H15: Calle 47 # 11-9 | I15: =_xlfn.CONCAT(D15,"_",LEFT(F15,3),CHOOSE(RANDBETWEEN(1,2),"@gmail.com","@hotmail.com")) -> Andrés_Góm@gmail.com | J15: 4 | K15: 685465468 | U15: Desarrollador | V15: 109 | W15: 180
A16: 15 | B16: =TIPO_DOC!A2 -> 1 | C16: 4.8442342e+09 | D16: Andrés | F16: López | H16: Calle 65 # 17-1 | I16: =_xlfn.CONCAT(D16,"_",LEFT(F16,3),CHOOSE(RANDBETWEEN(1,2),"@gmail.com","@hotmail.com")) -> Andrés_Lóp@gmail.com | J16: 5 | K16: 685465468 | U16: QA | V16: 141 | W16: 63
A17: 16 | B17: =TIPO_DOC!A2 -> 1 | C17: 5.5108828e+09 | D17: Andrés | F17: Martínez | H17: Calle 50 # 20-47 | I17: =_xlfn.CONCAT(D17,"_",LEFT(F17,3),CHOOSE(RANDBETWEEN(1,2),"@gmail.com","@hotmail.com")) -> Andrés_Mar@gmail.com | J17: {=CIUDADES!A2:A6} -> 1 | K17: 685465468 | U17: Scrum Master | V17: 197 | W17: 187
A18: 17 | B18: =TIPO_DOC!A2 -> 1 | C18: 6.1775314e+09 | D18: Andrés | F18: Quintero | H18: Calle 76 # 16-13 | I18: =_xlfn.CONCAT(D18,"_",LEFT(F18,3),CHOOSE(RANDBETWEEN(1,2),"@gmail.com","@hotmail.com")) -> Andrés_Qui@gmail.com | J18: 2 | K18: 685465468 | U18: Tester | V18: 172 | W18: 134
A19: 18 | B19: =TIPO_DOC!A2 -> 1 | C19: 6.84418e+09 | D19: Andrés | F19: Ramírez | H19: Calle 45 # 4-11 | I19: =_xlfn.CONCAT(D19,"_",LEFT(F19,3),CHOOSE(RANDBETWEEN(1,2),"@gmail.com","@hotmail.com")) -> Andrés_Ram@hotmail.com | J19: 3 | K19: 685465468 | U19: QA | V19: 152 | W19: 197
A20: 19 | B20: =TIPO_DOC!A2 -> 1 | C20: 7.5108286e+09 | D20: Andrés | F20: Ruiz | H20: Calle 11 # 4-16 | I20: =_xlfn.CONCAT(D20,"_",LEFT(F20,3),CHOOSE(RANDBETWEEN(1,2),"@gmail.com","@hotmail.com")) -> Andrés_Rui@gmail.com | J20: 4 | K20: 685465468 | U20: Diseñadora | V20: 156 | W20: 52
A21: 20 | B21: =TIPO_DOC!A2 -> 1 | C21: 8177477186 | D21: Andrés | F21: Torres | H21: Calle 62 # 5-27 | I21: =_xlfn.CONCAT(D21,"_",LEFT(F21,3),CHOOSE(RANDBETWEEN(1,2),"@gmail.com","@hotmail.com")) -> Andrés_Tor@gmail.com | J21: 5 | K21: 685465468 | U21: QA | V21: 90
U22: Diseñadora | V22: 168
U23: Product Owner | V23: 198 | W23: 99
U24: Scrum Master | V24: 56 | W24: 187
U25: QA | V25: 100 | W25: 124
U26: Analista | V26: 143 | W26: 151
U27: Analista | V27: 159 | W27: 158
U28: Tester | V28: 135 | W28: 188
U29: Product Owner | V29: 142 | W29: 51
U30: Analista | V30: 130 | W30: 121
U31: Diseñadora | V31: 47 | W31: 42
U32: Scrum Master | V32: 49 | W32: 191
U33: Product Owner | V33: 137 | W33: 49
U34: Scrum Master | V34: 78 | W34: 149
... U38: Tester | V38: 45 | W38: 71
U39: Tester | V39: 56
U40: Diseñadora | V40: 68 | W40: 176
U41: Diseñadora | V41: 77
U42: Product Owner | V42: 97 | W42: 178
U43: Diseñadora | V43: 53 | W43: 196
...

Sheet INFORMACION_PROYECTO
A1: id_info_proyecto (*)PK | B1: proyecto (*) N:1 (FK) | C1: id_empleado (*)FK(N:1) | D1: id_rol (*)FK(N:1) | E1: actividad_empleados (*)FK(N:1) | F1: horas_laboradas (*) | G1: costo_hora (*)
A2: 1 | B2: {=_xlfn.XLOOKUP('0FN'!A2:A11,PROYECTO!A2:A11,PROYECTO!A2:A11)} -> 1 | C2: {=_xlfn.XLOOKUP(EMPLEADOS!T2:T31,EMPLEADOS!S2:S114,EMPLEADOS!A2:A114)} -> 1 | D2: {=_xlfn.XLOOKUP(EMPLEADOS!U2:U31,ROLES!B2:B8,ROLES!A2:A8)} -> 1 | E2: {=_xlfn.XLOOKUP('0FN'!I2:I31,ACTIVIDADES_EMPLEADOS!B2:B12,ACTIVIDADES_EMPLEADOS!A2:A12)} -> 1 | F2: =EMPLEADOS!V2 -> 80 | G2: 7300
A3: 2 | B3: 2 | C3: 1 | D3: 1 | E3: 2 | F3: =EMPLEADOS!V3 -> 120 | G3: 5500
A4: 3 | B4: 3 | C4: 1 | D4: 1 | E4: 3 | F4: =EMPLEADOS!V4 -> 143 | G4: 10200
A5: 4 | B5: 4 | C5: 1 | D5: 2 | E5: 4 | F5: =EMPLEADOS!V5 -> 167 | G5: 27500
A6: 5 | B6: 5 | C6: 1 | D6: 3 | E6: 3 | F6: =EMPLEADOS!V6 -> 195 | G6: 14200
A7: 6 | B7: 6 | C7: 1 | D7: 1 | E7: 5 | F7: =EMPLEADOS!V7 -> 193 | G7: 12000
A8: 7 | B8: 7 | C8: 1 | D8: 3 | E8: 5 | F8: =EMPLEADOS!V8 -> 46 | G8: 23000
A9: 8 | B9: 8 | C9: 1 | D9: 6 | E9: 6 | F9: =EMPLEADOS!V9 -> 61 | G9: 7300
A10: 9 | B10: 9 | C10: 1 | D10: 5 | E10: 5 | F10: =EMPLEADOS!V10 -> 43 | G10: 5500
A11: 10 | B11: 10 | C11: 1 | D11: 3 | E11: 3 | F11: =EMPLEADOS!V11 -> 72 | G11: 10200
A12: 11 | B12: {=PROYECTO!A2:A11} -> 1 | C12: 1 | D12: 3 | E12: 6 | F12: =EMPLEADOS!V12 -> 99 | G12: 14200
A13: 12 | B13: 2 | C13: 1 | D13: 6 | E13: 6 | F13: =EMPLEADOS!V13 -> 50 | G13: 12000
A14: 13 | B14: 3 | C14: 1 | D14: 2 | E14: 5 | F14: =EMPLEADOS!V14 -> 53 | G14: 23000
A15: 14 | B15: 4 | C15: 1 | D15: 6 | E15: 3 | F15: =EMPLEADOS!V15 -> 109 | G15: 14200
A16: 15 | B16: 5 | C16: 1 | D16: 5 | E16: 4 | F16: =EMPLEADOS!V16 -> 141 | G16: 12000
A17: 16 | B17: 6 | C17: 1 | D17: 3 | E17: 3 | F17: =EMPLEADOS!V17 -> 197 | G17: 23000
A18: 17 | B18: 7 | C18: 1 | D18: 4 | E18: 4 | F18: =EMPLEADOS!V18 -> 172 | G18: 27500
A19: 18 | B19: 8 | C19: 1 | D19: 5 | E19: 1 | F19: =EMPLEADOS!V19 -> 152 | G19: 14200
A20: 19 | B20: 9 | C20: 1 | D20: 1 | E20: 7 | F20: =EMPLEADOS!V20 -> 156 | G20: 12000
A21: 20 | B21: 10 | C21: 1 | D21: 5 | E21: 6 | F21: =EMPLEADOS!V21 -> 90 | G21: 5500
A22: 21 | B22: {=PROYECTO!A2:A11} -> 1 | C22: 1 | D22: 1 | E22: 6 | F22: =EMPLEADOS!V22 -> 168 | G22: 10200
A23: 22 | B23: 2 | C23: 1 | D23: 7 | E23: 1 | F23: =EMPLEADOS!V23 -> 198 | G23: 27500
A24: 23 | B24: 3 | C24: 1 | D24: 3 | E24: 1 | F24: =EMPLEADOS!V24 -> 56 | G24: 14200
A25: 24 | B25: 4 | C25: 1 | D25: 5 | E25: 1 | F25: =EMPLEADOS!V25 -> 100 | G25: 12000
A26: 25 | B26: 5 | C26: 1 | D26: 2 | E26: 7 | F26: =EMPLEADOS!V26 -> 143 | G26: 23000
A27: 26 | B27: 6 | C27: 1 | D27: 2 | E27: 4 | F27: =EMPLEADOS!V27 -> 159 | G27: 7300
A28: 27 | B28: 7 | C28: 1 | D28: 4 | E28: 7 | F28: =EMPLEADOS!V28 -> 135 | G28: 5500
A29: 28 | B29: 8 | C29: 1 | D29: 7 | E29: 3 | F29: =EMPLEADOS!V29 -> 142 | G29: 10200
A30: 29 | B30: 9 | C30: 1 | D30: 2 | E30: 7 | F30: =EMPLEADOS!V30 -> 130 | G30: 14200
A31: 30 | B31: 10 | C31: 1 | D31: 1 | E31: 4 | F31: =EMPLEADOS!V31 -> 47 | G31: 12000

Sheet ROLES
A1: id_rol (*) PK | B1: nombre_rol (*)
A2: 1 | B2: Diseñadora
A3: 2 | B3: Analista
A4: 3 | B4: Scrum Master
A5: 4 | B5: Tester
A6: 5 | B6: QA
A7: 6 | B7: Desarrollador
A8: 7 | B8: Product Owner

Sheet ACTIVIDADES_EMPLEADOS
A1: id_actividades (*) PK | B1: nombre_actividades (*)
A2: 1 | B2: Diseño UI
A3: 2 | B3: Levantamiento
A4: 3 | B4: Deploy
A5: 4 | B5: Documentación
A6: 5 | B6: Desarrollo Backend
A7: 6 | B7: Planeación Sprint
A8: 7 | B8: Revisión Código
A9: 8 | B9: Pruebas
A10: 9 | B10: Mantenimiento
A11: 10 | B11: Desarrollo Frontend
A12: 11 | B12: Ajustes finales

Sheet TIPO_DOC
A1: id_tipo_doc (*) PK | B1: tipo_doc(*)
A2: 1 | B2: cédula
A3: 2 | B3: pasaporte
A4: 3 | B4: ppt
A5: 4 | B5: nit
